Workbook
Name DNSZones: Zones!$J$2:$J$9
Name NodeHostnames: Nodes!$U$2:$U$51
Name NodeIPs: Nodes!$P$2:$P$51

Sheet Zones
A1: Network | B1: VLAN ID | C1: Interface Name | D1: DNS Server | E1: Gateway IP | F1: Search Domain | G1: VLAN Name | H1: DHCP Start | I1: DHCP End | J1: DNS Zone | K1: DNS Views | L1: Address List Name | M1: Hairpin Allowed | N1: Allow Management | O1: Trust Level
A2: 192.168.10.0/24 | B2: 10 | C2: vlan10-mgmt | D2: 192.168.100.2 | E2: 192.168.10.1 | F2: moyer.wtf | G2: mgmt | H2: 192.168.10.100 | I2: 192.168.10.254 | J2: mgmt.moyer.wtf | K2: internal | L2: =IF(NOT(ISBLANK($G2)), CONCATENATE(G2, "-lan"), "") -> mgmt-lan | M2: TRUE | N2: TRUE | O2: Trusted
A3: 192.168.20.0/24 | B3: 20 | C3: vlan20-dmz | D3: 192.168.100.2 | E3: 192.168.20.1 | F3: moyer.wtf | G3: dmz | H3: 192.168.20.100 | I3: 192.168.20.254 | J3: dmz.moyer.wtf | K3: internal | L3: =IF(NOT(ISBLANK($G3)), CONCATENATE(G3, "-lan"), "") -> dmz-lan | M3: TRUE | N3: TRUE | O3: Semi-trusted
A4: 192.168.30.0/24 | B4: 30 | C4: vlan30-homelab | D4: 192.168.100.2 | E4: 192.168.30.1 | F4: moyer.wtf | G4: homelab | H4: 192.168.30.100 | I4: 192.168.30.254 | J4: homelab.moyer.wtf | K4: internal | L4: =IF(NOT(ISBLANK($G4)), CONCATENATE(G4, "-lan"), "") -> homelab-lan | M4: TRUE | N4: TRUE | O4: Trusted
A5: 192.168.100.0/24 | B5: 100 | C5: vlan100-clients | D5: 192.168.100.2 | E5: 192.168.100.1 | F5: moyer.wtf | G5: hivemind | H5: 192.168.100.100 | I5: 192.168.100.254 | J5: hivemind.moyer.wtf | K5: internal | L5: =IF(NOT(ISBLANK($G5)), CONCATENATE(G5, "-lan"), "") -> hivemind-lan | M5: TRUE | N5: FALSE | O5: Semi-trusted
A6: 207.144.81.217/24 | E6: 207.144.81.1 | G6: wan | J6: moyer.wtf | K6: internal, external | L6: wan-interface | M6: FALSE | N6: FALSE | O6: Untrusted
A7: 207.144.81.217/24 | E7: 207.144.81.1 | J7: thomasmoyer.org | K7: internal, external | L7: wan-interface | M7: FALSE | N7: FALSE | O7: Untrusted
J8: priv.moyer.wtf | K8: internal | L8: priv-lan | M8: FALSE | N8: FALSE | O8: Trusted
A9: 172.16.10.0/24 | G9: ceph | J9: ceph.moyer.wtf | K9: internal | L9: =IF(NOT(ISBLANK($G9)), CONCATENATE(G9, "-lan"), "") -> ceph-lan | M9: FALSE | N9: FALSE | O9: Trusted

Sheet Nodes
A1: Hostname | B1: Set up | C1: Tailscale logged in | D1: Accept TS Routes | E1: Kuma | F1: Grafana | G1: Backups | H1: Backups Tested | I1: VLAN | J1: Subnet | K1: VLAN ID | L1: Interface Name | M1: DNS Server | N1: Gateway IP | O1: Search Domain | P1: IP Address | Q1: Static/DHCP | R1: Device Type | S1: Interface | T1: MAC Address | U1: DNS Name | V1: Extra CNAMEs | W1: Disable CNAME | X1: Managed | Y1: Playbooks | Z1: Roles | AA1: Proxmox Node | AB1: Script URL | AC1: Oxidized Model | AD1: Skip Tailscale | AE1: Tailscale Install Method | AF1: Cores | AG1: RAM | AH1: Disk
A2: hexs | B2: TRUE | C2: TRUE | D2: FALSE | E2: TRUE | F2: FALSE | G2: FALSE | H2: FALSE | I2: mgmt | J2: {=XLOOKUP(I2, Zones[VLAN Name], Zones!$A$2:$F$9, "", -1)} -> 192.168.10.0/24 | K2: 10 | L2: vlan10-mgmt | M2: 192.168.100.2 | N2: 192.168.10.1 | O2: moyer.wtf | P2: 192.168.10.1 | Q2: Static | R2: Physical | S2: vlan10-mgmt | U2: {=IF(P2<>"", A2 & "." & XLOOKUP(P2, Zones!A:A, Zones!J:J, "", -1), "")} -> hexs.mgmt.moyer.wtf | W2: =IF(U2<>"", IF(COUNTIF(Services!$A:$A, U2)>0, TRUE, FALSE), "") -> TRUE | X2: FALSE | AC2: routeros | AD2: TRUE
A3: crs | B3: TRUE | C3: TRUE | D3: FALSE | E3: TRUE | F3: FALSE | G3: FALSE | H3: FALSE | I3: mgmt | J3: {=XLOOKUP(I3, Zones[VLAN Name], Zones!$A$2:$F$9, "", -1)} -> 192.168.10.0/24 | K3: 10 | L3: vlan10-mgmt | M3: 192.168.100.2 | N3: 192.168.10.1 | O3: moyer.wtf | P3: 192.168.10.2 | Q3: Static | R3: Physical | S3: vlan10-mgmt | U3: {=IF(P3<>"", A3 & "." & XLOOKUP(P3, Zones!A:A, Zones!J:J, "", -1), "")} -> crs.mgmt.moyer.wtf | W3: =IF(U3<>"", IF(COUNTIF(Services!$A:$A, U3)>0, TRUE, FALSE), "") -> TRUE | X3: FALSE | AC3: routeros | AD3: TRUE
A4: udr | B4: TRUE | C4: TRUE | D4: FALSE | E4: TRUE | F4: FALSE | G4: FALSE | H4: FALSE | I4: mgmt | J4: {=XLOOKUP(I4, Zones[VLAN Name], Zones!$A$2:$F$9, "", -1)} -> 192.168.10.0/24 | K4: 10 | L4: vlan10-mgmt | M4: 192.168.100.2 | N4: 192.168.10.1 | O4: moyer.wtf | P4: 192.168.10.3 | Q4: Static | R4: Physical | S4: vlan10-mgmt | U4: {=IF(P4<>"", A4 & "." & XLOOKUP(P4, Zones!A:A, Zones!J:J, "", -1), "")} -> udr.mgmt.moyer.wtf | W4: =IF(U4<>"", IF(COUNTIF(Services!$A:$A, U4)>0, TRUE, FALSE), "") -> FALSE | X4: FALSE | AD4: TRUE
A5: u6p-0 | B5: TRUE | C5: TRUE | D5: FALSE | E5: TRUE | F5: FALSE | G5: FALSE | H5: FALSE | I5: mgmt | J5: {=XLOOKUP(I5, Zones[VLAN Name], Zones!$A$2:$F$9, "", -1)} -> 192.168.10.0/24 | K5: 10 | L5: vlan10-mgmt | M5: 192.168.100.2 | N5: 192.168.10.1 | O5: moyer.wtf | P5: 192.168.10.4 | Q5: Static | R5: Physical | S5: eth0 | U5: {=IF(P5<>"", A5 & "." & XLOOKUP(P5, Zones!A:A, Zones!J:J, "", -1), "")} -> u6p-0.mgmt.moyer.wtf | W5: =IF(U5<>"", IF(COUNTIF(Services!$A:$A, U5)>0, TRUE, FALSE), "") -> FALSE | X5: FALSE | AD5: TRUE
A6: desktop-0 | B6: TRUE | C6: TRUE | D6: FALSE | E6: TRUE | F6: FALSE | G6: FALSE | H6: FALSE | I6: mgmt | J6: {=XLOOKUP(I6, Zones[VLAN Name], Zones!$A$2:$F$9, "", -1)} -> 192.168.10.0/24 | K6: 10 | L6: vlan10-mgmt | M6: 192.168.100.2 | N6: 192.168.10.1 | O6: moyer.wtf | P6: 192.168.10.6 | Q6: Static | R6: Physical | S6: nic0 | U6: {=IF(P6<>"", A6 & "." & XLOOKUP(P6, Zones!A:A, Zones!J:J, "", -1), "")} -> desktop-0.mgmt.moyer.wtf | W6: =IF(U6<>"", IF(COUNTIF(Services!$A:$A, U6)>0, TRUE, FALSE), "") -> FALSE | X6: TRUE | Y6: kanidm-client.yaml; node_exporter.yaml; apt-cacher-ng-client.yaml | Z6: pve;kanidm-linux-login;node_exporter;apt_cacher_client | AD6: FALSE | AE6: Tailscale Install Script
A7: meer5-0 | B7: TRUE | C7: TRUE | D7: FALSE | E7: TRUE | F7: FALSE | G7: FALSE | H7: FALSE | I7: mgmt | J7: {=XLOOKUP(I7, Zones[VLAN Name], Zones!$A$2:$F$9, "", -1)} -> 192.168.10.0/24 | K7: 10 | L7: vlan10-mgmt | M7: 192.168.100.2 | N7: 192.168.10.1 | O7: moyer.wtf | P7: 192.168.10.7 | Q7: Static | R7: Physical | S7: nic0 | U7: {=IF(P7<>"", A7 & "." & XLOOKUP(P7, Zones!A:A, Zones!J:J, "", -1), "")} -> meer5-0.mgmt.moyer.wtf | W7: =IF(U7<>"", IF(COUNTIF(Services!$A:$A, U7)>0, TRUE, FALSE), "") -> FALSE | X7: TRUE | Y7: kanidm-client.yaml; node_exporter.yaml; apt-cacher-ng-client.yaml | Z7: pve;kanidm-linux-login;node_exporter;apt_cacher_client | AD7: FALSE | AE7: Tailscale Install Script
A8: meer8-0 | B8: TRUE | C8: TRUE | D8: FALSE | E8: TRUE | F8: FALSE | G8: FALSE | H8: FALSE | I8: mgmt | J8: {=XLOOKUP(I8, Zones[VLAN Name], Zones!$A$2:$F$9, "", -1)} -> 192.168.10.0/24 | K8: 10 | L8: vlan10-mgmt | M8: 192.168.100.2 | N8: 192.168.10.1 | O8: moyer.wtf | P8: 192.168.10.8 | Q8: Static | R8: Physical | S8: nic0 | U8: {=IF(P8<>"", A8 & "." & XLOOKUP(P8, Zones!A:A, Zones!J:J, "", -1), "")} -> meer8-0.mgmt.moyer.wtf | W8: =IF(U8<>"", IF(COUNTIF(Services!$A:$A, U8)>0, TRUE, FALSE), "") -> FALSE | X8: TRUE | Y8: kanidm-client.yaml; node_exporter.yaml; apt-cacher-ng-client.yaml | Z8: pve;kanidm-linux-login;node_exporter;apt_cacher_client | AD8: FALSE | AE8: Tailscale Install Script
A9: meer8-1 | B9: TRUE | C9: TRUE | D9: FALSE | E9: TRUE | F9: FALSE | G9: FALSE | H9: FALSE | I9: mgmt | J9: {=XLOOKUP(I9, Zones[VLAN Name], Zones!$A$2:$F$9, "", -1)} -> 192.168.10.0/24 | K9: 10 | L9: vlan10-mgmt | M9: 192.168.100.2 | N9: 192.168.10.1 | O9: moyer.wtf | P9: 192.168.10.9 | Q9: Static | R9: Physical | S9: nic0 | U9: {=IF(P9<>"", A9 & "." & XLOOKUP(P9, Zones!A:A, Zones!J:J, "", -1), "")} -> meer8-1.mgmt.moyer.wtf | W9: =IF(U9<>"", IF(COUNTIF(Services!$A:$A, U9)>0, TRUE, FALSE), "") -> FALSE | X9: TRUE | Y9: kanidm-client.yaml; node_exporter.yaml; apt-cacher-ng-client.yaml | Z9: pve;kanidm-linux-login;node_exporter;apt_cacher_client | AD9: FALSE | AE9: Tailscale Install Script
A10: meer8-2 | B10: TRUE | C10: TRUE | D10: FALSE | E10: TRUE | F10: FALSE | G10: FALSE | H10: FALSE | I10: mgmt | J10: {=XLOOKUP(I10, Zones[VLAN Name], Zones!$A$2:$F$9, "", -1)} -> 192.168.10.0/24 | K10: 10 | L10: vlan10-mgmt | M10: 192.168.100.2 | N10: 192.168.10.1 | O10: moyer.wtf | P10: 192.168.10.10 | Q10: Static | R10: Physical | S10: nic0 | U10: {=IF(P10<>"", A10 & "." & XLOOKUP(P10, Zones!A:A, Zones!J:J, "", -1), "")} -> meer8-2.mgmt.moyer.wtf | W10: =IF(U10<>"", IF(COUNTIF(Services!$A:$A, U10)>0, TRUE, FALSE), "") -> FALSE | X10: TRUE | Y10: kanidm-client.yaml; node_exporter.yaml; apt-cacher-ng-client.yaml | Z10: pve;kanidm-linux-login;node_exporter;apt_cacher_client | AD10: FALSE | AE10: Tailscale Install Script
A11: pbs | B11: TRUE | C11: TRUE | D11: FALSE | E11: TRUE | F11: FALSE | H11: FALSE | I11: mgmt | J11: {=XLOOKUP(I11, Zones[VLAN Name], Zones!$A$2:$F$9, "", -1)} -> 192.168.10.0/24 | K11: 10 | L11: vlan10-mgmt | M11: 192.168.100.2 | N11: 192.168.10.1 | O11: moyer.wtf | P11: 192.168.10.11 | Q11: DHCP | R11: VM | S11: eth0 | T11: BC:24:11:22:78:1E | U11: {=IF(P11<>"", A11 & "." & XLOOKUP(P11, Zones!A:A, Zones!J:J, "", -1), "")} -> pbs.mgmt.moyer.wtf | W11: =IF(U11<>"", IF(COUNTIF(Services!$A:$A, U11)>0, TRUE, FALSE), "") -> TRUE | X11: TRUE | Y11: kanidm-client.yaml; node_exporter.yaml; apt-cacher-ng-client.yaml | Z11: pve;kanidm-linux-login;node_exporter;apt_cacher_client | AA11: desktop-0 | AD11: FALSE | AE11: None | AF11: 2 | AG11: 2048 | AH11: 10
A12: kanidm | B12: TRUE | C12: TRUE | D12: FALSE | E12: TRUE | F12: FALSE | G12: TRUE | H12: FALSE | I12: mgmt | J12: {=XLOOKUP(I12, Zones[VLAN Name], Zones!$A$2:$F$9, "", -1)} -> 192.168.10.0/24 | K12: 10 | L12: vlan10-mgmt | M12: 192.168.100.2 | N12: 192.168.10.1 | O12: moyer.wtf | P12: 192.168.10.12 | Q12: Static | R12: LXC | S12: eth0 | U12: {=IF(P12<>"", A12 & "." & XLOOKUP(P12, Zones!A:A, Zones!J:J, "", -1), "")} -> kanidm.mgmt.moyer.wtf | W12: =IF(U12<>"", IF(COUNTIF(Services!$A:$A, U12)>0, TRUE, FALSE), "") -> TRUE | X12: TRUE | Y12: kanidm.yaml; kanidm-client.yaml; node_exporter.yaml; apt-cacher-ng-client.yaml | Z12: pve;kanidm-linux-login;node_exporter;apt_cacher_client | AA12: meer8-1 | AB12: ct/docker.sh | AD12: FALSE | AE12: Proxmox Helper Script | AF12: 2 | AG12: 4096 | AH12: 12
A13: smtp-relay | B13: TRUE | C13: TRUE | D13: FALSE | E13: TRUE | F13: FALSE | G13: TRUE | H13: FALSE | I13: mgmt | J13: {=XLOOKUP(I13, Zones[VLAN Name], Zones!$A$2:$F$9, "", -1)} -> 192.168.10.0/24 | K13: 10 | L13: vlan10-mgmt | M13: 192.168.100.2 | N13: 192.168.10.1 | O13: moyer.wtf | P13: 192.168.10.14 | Q13: Static | R13: LXC | S13: eth0 | U13: {=IF(P13<>"", A13 & "." & XLOOKUP(P13, Zones!A:A, Zones!J:J, "", -1), "")} -> smtp-relay.mgmt.moyer.wtf | W13: =IF(U13<>"", IF(COUNTIF(Services!$A:$A, U13)>0, TRUE, FALSE), "") -> TRUE | X13: TRUE | Y13: smtp-relay.yaml; kanidm-client.yaml; node_exporter.yaml; apt-cacher-ng-client.yaml | Z13: kanidm-linux-login;node_exporter;apt_cacher_client | AA13: meer5-0 | AB13: ct/debian.sh | AD13: FALSE | AE13: Proxmox Helper Script | AF13: 1 | AG13: 512 | AH13: 4
A14: proxmox | I14: mgmt | J14: {=XLOOKUP(I14, Zones[VLAN Name], Zones!$A$2:$F$9, "", -1)} -> 192.168.10.0/24 | K14: 10 | L14: vlan10-mgmt | M14: 192.168.100.2 | N14: 192.168.10.1 | O14: moyer.wtf | P14: 192.168.10.15 | Q14: Static | R14: Custom | S14: vip | U14: {=IF(P14<>"", A14 & "." & XLOOKUP(P14, Zones!A:A, Zones!J:J, "", -1), "")} -> proxmox.mgmt.moyer.wtf | W14: =IF(U14<>"", IF(COUNTIF(Services!$A:$A, U14)>0, TRUE, FALSE), "") -> TRUE | X14: FALSE | AD14: TRUE | AE14: None
A15: uptime-kuma | B15: TRUE | C15: TRUE | D15: FALSE | F15: FALSE | G15: TRUE | H15: FALSE | I15: mgmt | J15: {=XLOOKUP(I15, Zones[VLAN Name], Zones!$A$2:$F$9, "", -1)} -> 192.168.10.0/24 | K15: 10 | L15: vlan10-mgmt | M15: 192.168.100.2 | N15: 192.168.10.1 | O15: moyer.wtf | P15: 192.168.10.16 | Q15: DHCP | R15: Physical | S15: eth0 | T15: D8:3A:DD:21:07:65 | U15: {=IF(P15<>"", A15 & "." & XLOOKUP(P15, Zones!A:A, Zones!J:J, "", -1), "")} -> uptime-kuma.mgmt.moyer.wtf | W15: =IF(U15<>"", IF(COUNTIF(Services!$A:$A, U15)>0, TRUE, FALSE), "") -> TRUE | X15: TRUE | Y15: uptime-kuma.yaml; kanidm-client.yaml; node_exporter.yaml; apt-cacher-ng-client.yaml | Z15: kanidm-linux-login;node_exporter;apt_cacher_client | AD15: FALSE | AE15: Tailscale Install Script
A16: prometheus | B16: FALSE | C16: TRUE | D16: FALSE | E16: FALSE | F16: FALSE | G16: TRUE | H16: FALSE | I16: mgmt | J16: {=XLOOKUP(I16, Zones[VLAN Name], Zones!$A$2:$F$9, "", -1)} -> 192.168.10.0/24 | K16: 10 | L16: vlan10-mgmt | M16: 192.168.100.2 | N16: 192.168.10.1 | O16: moyer.wtf | P16: 192.168.10.5 | Q16: DHCP | R16: LXC | S16: eth0 | T16: BC:24:11:3F:A4:AA | U16: {=IF(P16<>"", A16 & "." & XLOOKUP(P16, Zones!A:A, Zones!J:J, "", -1), "")} -> prometheus.mgmt.moyer.wtf | W16: =IF(U16<>"", IF(COUNTIF(Services!$A:$A, U16)>0, TRUE, FALSE), "") -> TRUE | X16: TRUE | Y16: kanidm-client.yaml; node_exporter.yaml; apt-cacher-ng-client.yaml; prometheus.yaml | Z16: kanidm-linux-login;node_exporter;apt_cacher_client | AA16: meer8-0 | AB16: ct/prometheus.sh | AD16: FALSE | AE16: Proxmox Helper Script | AF16: 1 | AG16: 2048 | AH16: 8
A17: grafana | B17: FALSE | C17: TRUE | D17: FALSE | E17: FALSE | G17: TRUE | H17: FALSE | I17: mgmt | J17: {=XLOOKUP(I17, Zones[VLAN Name], Zones!$A$2:$F$9, "", -1)} -> 192.168.10.0/24 | K17: 10 | L17: vlan10-mgmt | M17: 192.168.100.2 | N17: 192.168.10.1 | O17: moyer.wtf | P17: 192.168.10.13 | Q17: DHCP | R17: LXC | S17: eth0 | T17: BC:24:11:73:5C:35 | U17: {=IF(P17<>"", A17 & "." & XLOOKUP(P17, Zones!A:A, Zones!J:J, "", -1), "")} -> grafana.mgmt.moyer.wtf | W17: =IF(U17<>"", IF(COUNTIF(Services!$A:$A, U17)>0, TRUE, FALSE), "") -> TRUE | X17: TRUE | Y17: kanidm-client.yaml; node_exporter.yaml; apt-cacher-ng-client.yaml | Z17: kanidm-linux-login;node_exporter;apt_cacher_client | AA17: meer8-0 | AB17: ct/grafana.sh | AD17: FALSE | AE17: Proxmox Helper Script | AF17: 1 | AG17: 2048 | AH17: 8
A18: pihole | B18: TRUE | C18: TRUE | D18: FALSE | E18: TRUE | F18: FALSE | G18: FALSE | H18: FALSE | I18: hivemind | J18: {=XLOOKUP(I18, Zones[VLAN Name], Zones!$A$2:$F$9, "", -1)} -> 192.168.100.0/24 | K18: 100 | L18: vlan100-clients | M18: 192.168.100.2 | N18: 192.168.100.1 | O18: moyer.wtf | P18: 192.168.100.2 | Q18: Static | R18: Physical | S18: eth0 | U18: {=IF(P18<>"", A18 & "." & XLOOKUP(P18, Zones!A:A, Zones!J:J, "", -1), "")} -> pihole.hivemind.moyer.wtf | W18: =IF(U18<>"", IF(COUNTIF(Services!$A:$A, U18)>0, TRUE, FALSE), "") -> TRUE | X18: TRUE | Y18: pihole.yaml; kanidm-client.yaml; node_exporter.yaml; apt-cacher-ng-client.yaml | Z18: pihole_node;kanidm-linux-login;node_exporter;apt_cacher_client | AD18: FALSE | AE18: Tailscale Install Script
A19: laptop | B19: TRUE | C19: TRUE | D19: TRUE | G19: FALSE | H19: FALSE | I19: hivemind | J19: {=XLOOKUP(I19, Zones[VLAN Name], Zones!$A$2:$F$9, "", -1)} -> 192.168.100.0/24 | K19: 100 | L19: vlan100-clients | M19: 192.168.100.2 | N19: 192.168.100.1 | O19: moyer.wtf | P19: 192.168.100.53 | Q19: DHCP | R19: Physical | S19: wlan0 | T19: B0:4F:13:F5:06:C9 | U19: {=IF(P19<>"", A19 & "." & XLOOKUP(P19, Zones!A:A, Zones!J:J, "", -1), "")} -> laptop.hivemind.moyer.wtf | W19: =IF(U19<>"", IF(COUNTIF(Services!$A:$A, U19)>0, TRUE, FALSE), "") -> FALSE | X19: FALSE | AD19: TRUE
A20: laptop-wifi-dongle | B20: TRUE | C20: TRUE | I20: hivemind | J20: {=XLOOKUP(I20, Zones[VLAN Name], Zones!$A$2:$F$9, "", -1)} -> 192.168.100.0/24 | K20: 100 | L20: vlan100-clients | M20: 192.168.100.2 | N20: 192.168.100.1 | O20: moyer.wtf | P20: 192.168.100.54 | Q20: DHCP | R20: Physical | S20: wlan1 | T20: 04:7B:CB:2E:80:54 | U20: {=IF(P20<>"", A20 & "." & XLOOKUP(P20, Zones!A:A, Zones!J:J, "", -1), "")} -> laptop-wifi-dongle.hivemind.moyer.wtf | W20: =IF(U20<>"", IF(COUNTIF(Services!$A:$A, U20)>0, TRUE, FALSE), "") -> FALSE | X20: FALSE | AD20: FALSE
A21: laptop-monitor | B21: TRUE | C21: TRUE | I21: hivemind | J21: {=XLOOKUP(I21, Zones[VLAN Name], Zones!$A$2:$F$9, "", -1)} -> 192.168.100.0/24 | K21: 100 | L21: vlan100-clients | M21: 192.168.100.2 | N21: 192.168.100.1 | O21: moyer.wtf | P21: 192.168.100.55 | Q21: DHCP | R21: Physical | S21: eth0 | T21: E8:4E:06:B0:3F:30 | U21: {=IF(P21<>"", A21 & "." & XLOOKUP(P21, Zones!A:A, Zones!J:J, "", -1), "")} -> laptop-monitor.hivemind.moyer.wtf | W21: =IF(U21<>"", IF(COUNTIF(Services!$A:$A, U21)>0, TRUE, FALSE), "") -> FALSE | X21: FALSE | AD21: FALSE
A22: laptop-dock | B22: TRUE | C22: TRUE | I22: hivemind | J22: {=XLOOKUP(I22, Zones[VLAN Name], Zones!$A$2:$F$9, "", -1)} -> 192.168.100.0/24 | K22: 100 | L22: vlan100-clients | M22: 192.168.100.2 | N22: 192.168.100.1 | O22: moyer.wtf | P22: 192.168.100.56 | Q22: DHCP | R22: Physical | S22: eth0 | T22: 60:7D:09:93:BB:7F | U22: {=IF(P22<>"", A22 & "." & XLOOKUP(P22, Zones!A:A, Zones!J:J, "", -1), "")} -> laptop-dock.hivemind.moyer.wtf | W22: =IF(U22<>"", IF(COUNTIF(Services!$A:$A, U22)>0, TRUE, FALSE), "") -> FALSE | X22: FALSE | AD22: FALSE
A23: caddy | B23: TRUE | C23: TRUE | D23: FALSE | E23: TRUE | F23: FALSE | G23: TRUE | H23: FALSE | I23: dmz | J23: {=XLOOKUP(I23, Zones[VLAN Name], Zones!$A$2:$F$9, "", -1)} -> 192.168.20.0/24 | K23: 20 | L23: vlan20-dmz | M23: 192.168.100.2 | N23: 192.168.20.1 | O23: moyer.wtf | P23: 192.168.20.2 | Q23: Static | R23: LXC | S23: eth0 | U23: {=IF(P23<>"", A23 & "." & XLOOKUP(P23, Zones!A:A, Zones!J:J, "", -1), "")} -> caddy.dmz.moyer.wtf | W23: =IF(U23<>"", IF(COUNTIF(Services!$A:$A, U23)>0, TRUE, FALSE), "") -> FALSE | X23: TRUE | Y23: caddy-bootstrap.yaml; kanidm-client.yaml; node_exporter.yaml; apt-cacher-ng-client.yaml | Z23: kanidm-linux-login;node_exporter;apt_cacher_client | AA23: meer8-2 | AB23: ct/caddy.sh | AD23: FALSE | AE23: Proxmox Helper Script | AF23: 2 | AG23: 2048 | AH23: 6
A24: minecraft | B24: TRUE | C24: TRUE | D24: FALSE | E24: TRUE | F24: FALSE | G24: TRUE | H24: FALSE | I24: dmz | J24: {=XLOOKUP(I24, Zones[VLAN Name], Zones!$A$2:$F$9, "", -1)} -> 192.168.20.0/24 | K24: 20 | L24: vlan20-dmz | M24: 192.168.100.2 | N24: 192.168.20.1 | O24: moyer.wtf | P24: 192.168.20.3 | Q24: DHCP | R24: LXC | S24: eth0 | T24: BC:24:11:32:9C:26 | U24: {=IF(P24<>"", A24 & "." & XLOOKUP(P24, Zones!A:A, Zones!J:J, "", -1), "")} -> minecraft.dmz.moyer.wtf | W24: =IF(U24<>"", IF(COUNTIF(Services!$A:$A, U24)>0, TRUE, FALSE), "") -> TRUE | X24: TRUE | Y24: minecraft.yaml; kanidm-client.yaml; node_exporter.yaml; apt-cacher-ng-client.yaml | Z24: kanidm-linux-login;node_exporter;apt_cacher_client | AA24: meer8-1 | AB24: ct/docker.sh | AD24: FALSE | AE24: Proxmox Helper Script | AF24: 4 | AG24: 8192 | AH24: 40
A25: ts-router | B25: TRUE | C25: TRUE | D25: FALSE | E25: FALSE | F25: FALSE | G25: TRUE | H25: FALSE | I25: dmz | J25: {=XLOOKUP(I25, Zones[VLAN Name], Zones!$A$2:$F$9, "", -1)} -> 192.168.20.0/24 | K25: 20 | L25: vlan20-dmz | M25: 192.168.100.2 | N25: 192.168.20.1 | O25: moyer.wtf | P25: 192.168.20.4 | Q25: DHCP | R25: LXC | S25: eth0 | T25: BC:24:11:E3:98:8F | U25: {=IF(P25<>"", A25 & "." & XLOOKUP(P25, Zones!A:A, Zones!J:J, "", -1), "")} -> ts-router.dmz.moyer.wtf | W25: =IF(U25<>"", IF(COUNTIF(Services!$A:$A, U25)>0, TRUE, FALSE), "") -> FALSE | X25: TRUE | Y25: kanidm-client.yaml; node_exporter.yaml; ts-router.yaml; apt-cacher-ng-client.yaml | Z25: kanidm-linux-login;node_exporter;ts_router;apt_cacher_client | AA25: meer8-1 | AB25: ct/debian.sh | AD25: FALSE | AE25: Proxmox Helper Script | AF25: 1 | AG25: 2048 | AH25: 4
A26: syncthing | B26: TRUE | C26: TRUE | D26: FALSE | E26: TRUE | F26: FALSE | G26: TRUE | H26: FALSE | I26: homelab | J26: {=XLOOKUP(I26, Zones[VLAN Name], Zones!$A$2:$F$9, "", -1)} -> 192.168.30.0/24 | K26: 30 | L26: vlan30-homelab | M26: 192.168.100.2 | N26: 192.168.30.1 | O26: moyer.wtf | P26: 192.168.30.2 | Q26: DHCP | R26: LXC | S26: eth0 | T26: BC:24:11:B4:7D:E8 | U26: {=IF(P26<>"", A26 & "." & XLOOKUP(P26, Zones!A:A, Zones!J:J, "", -1), "")} -> syncthing.homelab.moyer.wtf | W26: =IF(U26<>"", IF(COUNTIF(Services!$A:$A, U26)>0, TRUE, FALSE), "") -> TRUE | X26: TRUE | Y26: kanidm-client.yaml; node_exporter.yaml; apt-cacher-ng-client.yaml | Z26: kanidm-linux-login;node_exporter;apt_cacher_client | AA26: meer5-0 | AB26: ct/syncthing.sh | AD26: FALSE | AE26: Proxmox Helper Script | AF26: 2 | AG26: 2048 | AH26: 40
A27: services | B27: TRUE | C27: TRUE | D27: FALSE | E27: TRUE | F27: FALSE | G27: TRUE | H27: FALSE | I27: homelab | J27: {=XLOOKUP(I27, Zones[VLAN Name], Zones!$A$2:$F$9, "", -1)} -> 192.168.30.0/24 | K27: 30 | L27: vlan30-homelab | M27: 192.168.100.2 | N27: 192.168.30.1 | O27: moyer.wtf | P27: 192.168.30.5 | Q27: DHCP | R27: LXC | S27: eth0 | T27: BC:24:11:10:29:A3 | U27: {=IF(P27<>"", A27 & "." & XLOOKUP(P27, Zones!A:A, Zones!J:J, "", -1), "")} -> services.homelab.moyer.wtf | W27: =IF(U27<>"", IF(COUNTIF(Services!$A:$A, U27)>0, TRUE, FALSE), "") -> TRUE | X27: TRUE | Y27: kanidm-client.yaml; services.yaml; node_exporter.yaml; apt-cacher-ng-client.yaml | Z27: kanidm-linux-login;node_exporter;apt_cacher_client | AA27: meer5-0 | AB27: ct/docker.sh | AD27: FALSE | AE27: Proxmox Helper Script | AF27: 1 | AG27: 512 | AH27: 4
A28: vaultwarden | B28: TRUE | C28: TRUE | D28: FALSE | E28: TRUE | F28: FALSE | G28: TRUE | H28: FALSE | I28: homelab | J28: {=XLOOKUP(I28, Zones[VLAN Name], Zones!$A$2:$F$9, "", -1)} -> 192.168.30.0/24 | K28: 30 | L28: vlan30-homelab | M28: 192.168.100.2 | N28: 192.168.30.1 | O28: moyer.wtf | P28: 192.168.30.6 | Q28: DHCP | R28: LXC | S28: eth0 | T28: BC:24:11:5B:1C:78 | U28: {=IF(P28<>"", A28 & "." & XLOOKUP(P28, Zones!A:A, Zones!J:J, "", -1), "")} -> vaultwarden.homelab.moyer.wtf | W28: =IF(U28<>"", IF(COUNTIF(Services!$A:$A, U28)>0, TRUE, FALSE), "") -> TRUE | X28: TRUE | Y28: kanidm-client.yaml; node_exporter.yaml; apt-cacher-ng-client.yaml | Z28: kanidm-linux-login;node_exporter;apt_cacher_client | AA28: meer8-0 | AB28: ct/vaultwarden.sh | AD28: FALSE | AE28: Proxmox Helper Script
A29: homarr | B29: TRUE | C29: TRUE | D29: FALSE | E29: TRUE | F29: FALSE | G29: TRUE | H29: FALSE | I29: homelab | J29: {=XLOOKUP(I29, Zones[VLAN Name], Zones!$A$2:$F$9, "", -1)} -> 192.168.30.0/24 | K29: 30 | L29: vlan30-homelab | M29: 192.168.100.2 | N29: 192.168.30.1 | O29: moyer.wtf | P29: 192.168.30.7 | Q29: DHCP | R29: LXC | S29: eth0 | T29: BC:24:11:F4:E2:BB | U29: {=IF(P29<>"", A29 & "." & XLOOKUP(P29, Zones!A:A, Zones!J:J, "", -1), "")} -> homarr.homelab.moyer.wtf | W29: =IF(U29<>"", IF(COUNTIF(Services!$A:$A, U29)>0, TRUE, FALSE), "") -> TRUE | X29: TRUE | Y29: kanidm-client.yaml; node_exporter.yaml; apt-cacher-ng-client.yaml | Z29: kanidm-linux-login;node_exporter;apt_cacher_client | AA29: meer5-0 | AB29: ct/homarr.sh | AD29: FALSE | AE29: Proxmox Helper Script | AF29: 2 | AG29: 2048 | AH29: 8
A30: jellyfin | B30: TRUE | C30: TRUE | D30: FALSE | E30: TRUE | F30: FALSE | G30: TRUE | H30: FALSE | I30: homelab | J30: {=XLOOKUP(I30, Zones[VLAN Name], Zones!$A$2:$F$9, "", -1)} -> 192.168.30.0/24 | K30: 30 | L30: vlan30-homelab | M30: 192.168.100.2 | N30: 192.168.30.1 | O30: moyer.wtf | P30: 192.168.30.9 | Q30: DHCP | R30: LXC | S30: eth0 | T30: BC:24:11:6A:DA:CE | U30: {=IF(P30<>"", A30 & "." & XLOOKUP(P30, Zones!A:A, Zones!J:J, "", -1), "")} -> jellyfin.homelab.moyer.wtf | W30: =IF(U30<>"", IF(COUNTIF(Services!$A:$A, U30)>0, TRUE, FALSE), "") -> TRUE | X30: TRUE | Y30: kanidm-client.yaml; node_exporter.yaml; apt-cacher-ng-client.yaml | Z30: kanidm-linux-login;node_exporter;apt_cacher_client | AA30: meer8-2 | AB30: ct/jellyfin.sh | AD30: FALSE | AE30: Proxmox Helper Script | AF30: 2 | AG30: 2048 | AH30: 1000
A31: openwebui | B31: TRUE | C31: TRUE | D31: FALSE | E31: TRUE | F31: FALSE | G31: TRUE | H31: FALSE | I31: homelab | J31: {=XLOOKUP(I31, Zones[VLAN Name], Zones!$A$2:$F$9, "", -1)} -> 192.168.30.0/24 | K31: 30 | L31: vlan30-homelab | M31: 192.168.100.2 | N31: 192.168.30.1 | O31: moyer.wtf | P31: 192.168.30.10 | Q31: DHCP | R31: LXC | S31: eth0 | T31: BC:24:11:16:DF:1F | U31: {=IF(P31<>"", A31 & "." & XLOOKUP(P31, Zones!A:A, Zones!J:J, "", -1), "")} -> openwebui.homelab.moyer.wtf | W31: =IF(U31<>"", IF(COUNTIF(Services!$A:$A, U31)>0, TRUE, FALSE), "") -> TRUE | X31: TRUE | Y31: kanidm-client.yaml; node_exporter.yaml; apt-cacher-ng-client.yaml | Z31: kanidm-linux-login;node_exporter;apt_cacher_client | AA31: desktop-0 | AB31: ct/openwebui.sh | AD31: FALSE | AE31: Proxmox Helper Script | AF31: 4 | AG31: 8192 | AH31: 48
A32: ollama | B32: TRUE | C32: TRUE | D32: FALSE | E32: TRUE | F32: FALSE | G32: TRUE | H32: FALSE | I32: homelab | J32: {=XLOOKUP(I32, Zones[VLAN Name], Zones!$A$2:$F$9, "", -1)} -> 192.168.30.0/24 | K32: 30 | L32: vlan30-homelab | M32: 192.168.100.2 | N32: 192.168.30.1 | O32: moyer.wtf | P32: 192.168.30.11 | Q32: DHCP | R32: VM | S32: eth0 | T32: BC:24:11:E5:E7:4F | U32: {=IF(P32<>"", A32 & "." & XLOOKUP(P32, Zones!A:A, Zones!J:J, "", -1), "")} -> ollama.homelab.moyer.wtf | W32: =IF(U32<>"", IF(COUNTIF(Services!$A:$A, U32)>0, TRUE, FALSE), "") -> TRUE | X32: TRUE | Y32: kanidm-client.yaml; ollama.yaml; node_exporter.yaml; apt-cacher-ng-client.yaml | Z32: kanidm-linux-login;node_exporter;apt_cacher_client | AA32: desktop-0 | AB32: vm/debian-13-vm.sh | AD32: FALSE | AE32: Proxmox Helper Script | AF32: 4 | AG32: 16384 | AH32: 1000
A33: gitea | B33: TRUE | C33: TRUE | D33: FALSE | E33: TRUE | F33: FALSE | G33: TRUE | H33: FALSE | I33: homelab | J33: {=XLOOKUP(I33, Zones[VLAN Name], Zones!$A$2:$F$9, "", -1)} -> 192.168.30.0/24 | K33: 30 | L33: vlan30-homelab | M33: 192.168.100.2 | N33: 192.168.30.1 | O33: moyer.wtf | P33: 192.168.30.12 | Q33: DHCP | R33: LXC | S33: eth0 | T33: BC:24:11:B2:C1:90 | U33: {=IF(P33<>"", A33 & "." & XLOOKUP(P33, Zones!A:A, Zones!J:J, "", -1), "")} -> gitea.homelab.moyer.wtf | W33: =IF(U33<>"", IF(COUNTIF(Services!$A:$A, U33)>0, TRUE, FALSE), "") -> TRUE | X33: TRUE | Y33: kanidm-client.yaml; node_exporter.yaml; apt-cacher-ng-client.yaml | Z33: kanidm-linux-login;node_exporter;apt_cacher_client | AA33: meer8-0 | AB33: ct/gitea.sh | AD33: FALSE | AE33: Proxmox Helper Script | AF33: 1 | AG33: 1024 | AH33: 100
A34: gitea-runner | B34: TRUE | C34: TRUE | D34: FALSE | E34: TRUE | F34: FALSE | G34: TRUE | H34: FALSE | I34: homelab | J34: {=XLOOKUP(I34, Zones[VLAN Name], Zones!$A$2:$F$9, "", -1)} -> 192.168.30.0/24 | K34: 30 | L34: vlan30-homelab | M34: 192.168.100.2 | N34: 192.168.30.1 | O34: moyer.wtf | P34: 192.168.30.13 | Q34: DHCP | R34: LXC | S34: eth0 | T34: BC:24:11:41:D7:2E | U34: {=IF(P34<>"", A34 & "." & XLOOKUP(P34, Zones!A:A, Zones!J:J, "", -1), "")} -> gitea-runner.homelab.moyer.wtf | W34: =IF(U34<>"", IF(COUNTIF(Services!$A:$A, U34)>0, TRUE, FALSE), "") -> TRUE | X34: TRUE | Y34: kanidm-client.yaml; gitea-runner.yaml; node_exporter.yaml; apt-cacher-ng-client.yaml | Z34: kanidm-linux-login;node_exporter;apt_cacher_client | AA34: meer8-1 | AB34: ct/docker.sh | AD34: FALSE | AE34: Proxmox Helper Script | AF34: 2 | AG34: 2048 | AH34: 100
A35: www | B35: TRUE | C35: TRUE | D35: FALSE | E35: TRUE | F35: FALSE | G35: TRUE | H35: FALSE | I35: homelab | J35: {=XLOOKUP(I35, Zones[VLAN Name], Zones!$A$2:$F$9, "", -1)} -> 192.168.30.0/24 | K35: 30 | L35: vlan30-homelab | M35: 192.168.100.2 | N35: 192.168.30.1 | O35: moyer.wtf | P35: 192.168.30.14 | Q35: DHCP | R35: LXC | S35: eth0 | T35: BC:24:11:E7:EB:4D | U35: {=IF(P35<>"", A35 & "." & XLOOKUP(P35, Zones!A:A, Zones!J:J, "", -1), "")} -> www.homelab.moyer.wtf | W35: =IF(U35<>"", IF(COUNTIF(Services!$A:$A, U35)>0, TRUE, FALSE), "") -> TRUE | X35: TRUE | Y35: kanidm-client.yaml; www.yaml; node_exporter.yaml; apt-cacher-ng-client.yaml | Z35: kanidm-linux-login;node_exporter;apt_cacher_client | AA35: meer8-2 | AB35: ct/docker.sh | AD35: FALSE | AE35: Proxmox Helper Script | AF35: 1 | AG35: 512 | AH35: 10
A36: firefly-iii | B36: TRUE | C36: TRUE | D36: FALSE | E36: TRUE | F36: FALSE | G36: TRUE | H36: FALSE | I36: homelab | J36: {=XLOOKUP(I36, Zones[VLAN Name], Zones!$A$2:$F$9, "", -1)} -> 192.168.30.0/24 | K36: 30 | L36: vlan30-homelab | M36: 192.168.100.2 | N36: 192.168.30.1 | O36: moyer.wtf | P36: 192.168.30.15 | Q36: DHCP | R36: LXC | S36: eth0 | T36: BC:24:11:91:03:17 | U36: {=IF(P36<>"", A36 & "." & XLOOKUP(P36, Zones!A:A, Zones!J:J, "", -1), "")} -> firefly-iii.homelab.moyer.wtf | W36: =IF(U36<>"", IF(COUNTIF(Services!$A:$A, U36)>0, TRUE, FALSE), "") -> TRUE | X36: TRUE | Y36: kanidm-client.yaml; node_exporter.yaml; apt-cacher-ng-client.yaml | Z36: kanidm-linux-login;node_exporter;apt_cacher_client | AA36: meer8-0 | AB36: ct/firefly.sh | AD36: FALSE | AE36: Proxmox Helper Script | AF36: 2 | AG36: 2048 | AH36: 10
A37: freshrss | B37: TRUE | C37: TRUE | D37: FALSE | E37: TRUE | F37: FALSE | G37: TRUE | H37: FALSE | I37: homelab | J37: {=XLOOKUP(I37, Zones[VLAN Name], Zones!$A$2:$F$9, "", -1)} -> 192.168.30.0/24 | K37: 30 | L37: vlan30-homelab | M37: 192.168.100.2 | N37: 192.168.30.1 | O37: moyer.wtf | P37: 192.168.30.16 | Q37: DHCP | R37: LXC | S37: eth0 | T37: BC:24:11:5D:EC:F3 | U37: {=IF(P37<>"", A37 & "." & XLOOKUP(P37, Zones!A:A, Zones!J:J, "", -1), "")} -> freshrss.homelab.moyer.wtf | W37: =IF(U37<>"", IF(COUNTIF(Services!$A:$A, U37)>0, TRUE, FALSE), "") -> TRUE | X37: TRUE | Y37: kanidm-client.yaml; node_exporter.yaml; apt-cacher-ng-client.yaml | Z37: kanidm-linux-login;node_exporter;apt_cacher_client | AA37: meer8-1 | AB37: ct/freshrss.sh | AD37: FALSE | AE37: Proxmox Helper Script | AF37: 2 | AG37: 1024 | AH37: 10
A38: guac | B38: TRUE | C38: TRUE | D38: FALSE | E38: TRUE | F38: FALSE | G38: TRUE | H38: FALSE | I38: homelab | J38: {=XLOOKUP(I38, Zones[VLAN Name], Zones!$A$2:$F$9, "", -1)} -> 192.168.30.0/24 | K38: 30 | L38: vlan30-homelab | M38: 192.168.100.2 | N38: 192.168.30.1 | O38: moyer.wtf | P38: 192.168.30.17 | Q38: DHCP | R38: LXC | S38: eth0 | T38: BC:24:11:09:C7:5A | U38: {=IF(P38<>"", A38 & "." & XLOOKUP(P38, Zones!A:A, Zones!J:J, "", -1), "")} -> guac.homelab.moyer.wtf | W38: =IF(U38<>"", IF(COUNTIF(Services!$A:$A, U38)>0, TRUE, FALSE), "") -> TRUE | X38: TRUE | Y38: kanidm-client.yaml; kanidm-ldap.yaml; node_exporter.yaml; apt-cacher-ng-client.yaml | Z38: kanidm-linux-login; kanidm-ldap;node_exporter;apt_cacher_client | AA38: meer8-2 | AB38: ct/apache-guacamole.sh | AD38: FALSE | AE38: Proxmox Helper Script | AF38: 1 | AG38: 2048 | AH38: 4
A39: paperclip | B39: TRUE | C39: TRUE | D39: FALSE | E39: TRUE | F39: FALSE | G39: TRUE | H39: FALSE | I39: homelab | J39: {=XLOOKUP(I39, Zones[VLAN Name], Zones!$A$2:$F$9, "", -1)} -> 192.168.30.0/24 | K39: 30 | L39: vlan30-homelab | M39: 192.168.100.2 | N39: 192.168.30.1 | O39: moyer.wtf | P39: 192.168.30.18 | Q39: DHCP | R39: LXC | S39: eth0 | T39: BC:24:11:B7:75:10 | U39: {=IF(P39<>"", A39 & "." & XLOOKUP(P39, Zones!A:A, Zones!J:J, "", -1), "")} -> paperclip.homelab.moyer.wtf | W39: =IF(U39<>"", IF(COUNTIF(Services!$A:$A, U39)>0, TRUE, FALSE), "") -> TRUE | X39: TRUE | Y39: kanidm-client.yaml; node_exporter.yaml; apt-cacher-ng-client.yaml | Z39: kanidm-linux-login;node_exporter;apt_cacher_client | AA39: desktop-0 | AD39: FALSE | AE39: None | AF39: 4 | AG39: 4096 | AH39: 100
A40: oxidized | B40: TRUE | C40: TRUE | D40: FALSE | E40: FALSE | F40: FALSE | G40: TRUE | H40: FALSE | I40: homelab | J40: {=XLOOKUP(I40, Zones[VLAN Name], Zones!$A$2:$F$9, "", -1)} -> 192.168.30.0/24 | K40: 30 | L40: vlan30-homelab | M40: 192.168.100.2 | N40: 192.168.30.1 | O40: moyer.wtf | P40: 192.168.30.19 | Q40: DHCP | R40: LXC | S40: eth0 | T40: BC:24:11:E5:D0:D7 | U40: {=IF(P40<>"", A40 & "." & XLOOKUP(P40, Zones!A:A, Zones!J:J, "", -1), "")} -> oxidized.homelab.moyer.wtf | W40: =IF(U40<>"", IF(COUNTIF(Services!$A:$A, U40)>0, TRUE, FALSE), "") -> TRUE | X40: TRUE | Y40: kanidm-client.yaml; oxidized.yaml; node_exporter.yaml; apt-cacher-ng-client.yaml | Z40: kanidm-linux-login;node_exporter;apt_cacher_client | AA40: meer5-0 | AB40: ct/docker.sh | AD40: FALSE | AE40: Proxmox Helper Script | AF40: 1 | AG40: 512 | AH40: 10
...

Sheet Services
A1: Hostname | B1: IP Address | C1: Subnet | D1: Backend Port | E1: Protocol | F1: Service name | G1: Ingress | H1: Exposure | I1: DNS Zone | J1: Frontend Hostname | K1: Frontend Port | L1: TLS | M1: Extra CNAMEs | N1: Default CNAME Target | O1: Include in services | P1: Font Awesome Class
A2: hexs.mgmt.moyer.wtf | B2: {=XLOOKUP(A2, NodeHostnames, NodeIPs, "")} -> 192.168.10.1 | C2: {=XLOOKUP(B2, Zones!$A$2:$A$9, Zones!$A$2:$A$9, "", -1)} -> 192.168.10.0/24 | D2: 80 | E2: TCP | F2: hEX S Management UI | G2: caddy | H2: private | I2: priv.moyer.wtf | J2: =IF(A2 <> "", LEFT(A2, FIND(".", A2) - 1) & "." & I2, "") -> hexs.priv.moyer.wtf | K2: 443 | L2: FALSE | N2: TRUE | O2: FALSE
A3: proxmox.mgmt.moyer.wtf | B3: {=XLOOKUP(A3, NodeHostnames, NodeIPs, "")} -> 192.168.10.15 | C3: {=XLOOKUP(B3, Zones!$A$2:$A$9, Zones!$A$2:$A$9, "", -1)} -> 192.168.10.0/24 | D3: 8006 | E3: TCP | F3: Proxmox | G3: caddy | H3: private | I3: priv.moyer.wtf | J3: =IF(A3 <> "", LEFT(A3, FIND(".", A3) - 1) & "." & I3, "") -> proxmox.priv.moyer.wtf | K3: 443 | L3: TRUE | N3: TRUE | O3: TRUE | P3: fa-solid fa-boxes-stacked
A4: crs.mgmt.moyer.wtf | B4: {=XLOOKUP(A4, NodeHostnames, NodeIPs, "")} -> 192.168.10.2 | C4: {=XLOOKUP(B4, Zones!$A$2:$A$9, Zones!$A$2:$A$9, "", -1)} -> 192.168.10.0/24 | D4: 80 | E4: TCP | F4: CRS Management UI | G4: caddy | H4: private | I4: priv.moyer.wtf | J4: =IF(A4 <> "", LEFT(A4, FIND(".", A4) - 1) & "." & I4, "") -> crs.priv.moyer.wtf | K4: 443 | L4: FALSE | N4: TRUE | O4: FALSE
A5: pihole.hivemind.moyer.wtf | B5: {=XLOOKUP(A5, NodeHostnames, NodeIPs, "")} -> 192.168.100.2 | C5: {=XLOOKUP(B5, Zones!$A$2:$A$9, Zones!$A$2:$A$9, "", -1)} -> 192.168.100.0/24 | D5: 80 | E5: TCP | F5: Pihole | G5: caddy | H5: private | I5: priv.moyer.wtf | J5: =IF(A5 <> "", LEFT(A5, FIND(".", A5) - 1) & "." & I5, "") -> pihole.priv.moyer.wtf | K5: 443 | L5: FALSE | N5: TRUE | O5: TRUE | P5: fa-solid fa-shield-halved
A6: kanidm.mgmt.moyer.wtf | B6: {=XLOOKUP(A6, NodeHostnames, NodeIPs, "")} -> 192.168.10.12 | C6: {=XLOOKUP(B6, Zones!$A$2:$A$9, Zones!$A$2:$A$9, "", -1)} -> 192.168.10.0/24 | D6: 443 | E6: TCP | F6: Kanidm | G6: caddy | H6: public | I6: moyer.wtf | J6: =IF(A6 <> "", LEFT(A6, FIND(".", A6) - 1) & "." & I6, "") -> kanidm.moyer.wtf | K6: 443 | L6: TRUE | N6: TRUE | O6: TRUE | P6: fa-solid fa-id-card
A7: kanidm.mgmt.moyer.wtf | B7: {=XLOOKUP(A7, NodeHostnames, NodeIPs, "")} -> 192.168.10.12 | C7: {=XLOOKUP(B7, Zones!$A$2:$A$9, Zones!$A$2:$A$9, "", -1)} -> 192.168.10.0/24 | D7: 636 | E7: TCP | F7: Kanidm LDAPS Interface | G7: direct | H7: local | I7: moyer.wtf | J7: =IF(A7 <> "", LEFT(A7, FIND(".", A7) - 1) & "." & I7, "") -> kanidm.moyer.wtf | L7: FALSE | O7: FALSE
A8: smtp-relay.mgmt.moyer.wtf | B8: {=XLOOKUP(A8, NodeHostnames, NodeIPs, "")} -> 192.168.10.14 | C8: {=XLOOKUP(B8, Zones!$A$2:$A$9, Zones!$A$2:$A$9, "", -1)} -> 192.168.10.0/24 | D8: 25 | E8: TCP | F8: SMTP Relay | G8: direct | H8: local | I8: moyer.wtf | J8: =IF(A8 <> "", LEFT(A8, FIND(".", A8) - 1) & "." & I8, "") -> smtp-relay.moyer.wtf | L8: FALSE | N8: TRUE | O8: FALSE
A9: pihole.hivemind.moyer.wtf | B9: {=XLOOKUP(A9, NodeHostnames, NodeIPs, "")} -> 192.168.100.2 | C9: {=XLOOKUP(B9, Zones!$A$2:$A$9, Zones!$A$2:$A$9, "", -1)} -> 192.168.100.0/24 | D9: 53 | E9: UDP | F9: Pihole DNS - UDP | G9: direct | H9: private | I9: priv.moyer.wtf | J9: =IF(A9 <> "", LEFT(A9, FIND(".", A9) - 1) & "." & I9, "") -> pihole.priv.moyer.wtf | O9: FALSE
A10: pihole.hivemind.moyer.wtf | B10: {=XLOOKUP(A10, NodeHostnames, NodeIPs, "")} -> 192.168.100.2 | C10: {=XLOOKUP(B10, Zones!$A$2:$A$9, Zones!$A$2:$A$9, "", -1)} -> 192.168.100.0/24 | D10: 53 | E10: TCP | F10: Pihole DNS - TCP | G10: direct | H10: private | I10: priv.moyer.wtf | J10: =IF(A10 <> "", LEFT(A10, FIND(".", A10) - 1) & "." & I10, "") -> pihole.priv.moyer.wtf | O10: FALSE
A11: minecraft.dmz.moyer.wtf | B11: {=XLOOKUP(A11, NodeHostnames, NodeIPs, "")} -> 192.168.20.3 | C11: {=XLOOKUP(B11, Zones!$A$2:$A$9, Zones!$A$2:$A$9, "", -1)} -> 192.168.20.0/24 | D11: 25565 | E11: TCP | F11: Minecraft | G11: direct | H11: public | I11: moyer.wtf | J11: =IF(A11 <> "", LEFT(A11, FIND(".", A11) - 1) & "." & I11, "") -> minecraft.moyer.wtf | K11: 25565 | N11: TRUE | O11: FALSE | P11: fa-solid fa-cube
A12: minecraft.dmz.moyer.wtf | B12: {=XLOOKUP(A12, NodeHostnames, NodeIPs, "")} -> 192.168.20.3 | C12: {=XLOOKUP(B12, Zones!$A$2:$A$9, Zones!$A$2:$A$9, "", -1)} -> 192.168.20.0/24 | D12: 25565 | E12: UDP | F12: Minecraft Java - UDP | G12: direct | H12: public | I12: moyer.wtf | J12: =IF(A12 <> "", LEFT(A12, FIND(".", A12) - 1) & "." & I12, "") -> minecraft.moyer.wtf | K12: 25565 | O12: FALSE
A13: minecraft.dmz.moyer.wtf | B13: {=XLOOKUP(A13, NodeHostnames, NodeIPs, "")} -> 192.168.20.3 | C13: {=XLOOKUP(B13, Zones!$A$2:$A$9, Zones!$A$2:$A$9, "", -1)} -> 192.168.20.0/24 | D13: 19132 | E13: UDP | F13: Minecraft Bedrock | G13: direct | H13: public | I13: moyer.wtf | J13: =IF(A13 <> "", LEFT(A13, FIND(".", A13) - 1) & "." & I13, "") -> minecraft.moyer.wtf | K13: 19132 | O13: FALSE
A14: syncthing.homelab.moyer.wtf | B14: {=XLOOKUP(A14, NodeHostnames, NodeIPs, "")} -> 192.168.30.2 | C14: {=XLOOKUP(B14, Zones!$A$2:$A$9, Zones!$A$2:$A$9, "", -1)} -> 192.168.30.0/24 | D14: 8384 | E14: TCP | F14: Syncthing | G14: caddy | H14: private | I14: priv.moyer.wtf | J14: =IF(A14 <> "", LEFT(A14, FIND(".", A14) - 1) & "." & I14, "") -> syncthing.priv.moyer.wtf | K14: 443 | L14: FALSE | N14: TRUE | O14: TRUE | P14: fa-solid fa-arrows-rotate
A15: syncthing.homelab.moyer.wtf | B15: {=XLOOKUP(A15, NodeHostnames, NodeIPs, "")} -> 192.168.30.2 | C15: {=XLOOKUP(B15, Zones!$A$2:$A$9, Zones!$A$2:$A$9, "", -1)} -> 192.168.30.0/24 | D15: 22000 | E15: TCP | F15: Syncthing Sync - TCP | G15: direct | H15: private | I15: priv.moyer.wtf | J15: =IF(A15 <> "", LEFT(A15, FIND(".", A15) - 1) & "." & I15, "") -> syncthing.priv.moyer.wtf | O15: FALSE
A16: syncthing.homelab.moyer.wtf | B16: {=XLOOKUP(A16, NodeHostnames, NodeIPs, "")} -> 192.168.30.2 | C16: {=XLOOKUP(B16, Zones!$A$2:$A$9, Zones!$A$2:$A$9, "", -1)} -> 192.168.30.0/24 | D16: 22000 | E16: UDP | F16: Syncthing Sync - UDP | G16: direct | H16: private | I16: priv.moyer.wtf | J16: =IF(A16 <> "", LEFT(A16, FIND(".", A16) - 1) & "." & I16, "") -> syncthing.priv.moyer.wtf | O16: FALSE
A17: syncthing.homelab.moyer.wtf | B17: {=XLOOKUP(A17, NodeHostnames, NodeIPs, "")} -> 192.168.30.2 | C17: {=XLOOKUP(B17, Zones!$A$2:$A$9, Zones!$A$2:$A$9, "", -1)} -> 192.168.30.0/24 | D17: 21027 | E17: UDP | F17: Syncthing Discovery | G17: direct | H17: private | I17: priv.moyer.wtf | J17: =IF(A17 <> "", LEFT(A17, FIND(".", A17) - 1) & "." & I17, "") -> syncthing.priv.moyer.wtf | O17: FALSE
A18: vaultwarden.homelab.moyer.wtf | B18: {=XLOOKUP(A18, NodeHostnames, NodeIPs, "")} -> 192.168.30.6 | C18: {=XLOOKUP(B18, Zones!$A$2:$A$9, Zones!$A$2:$A$9, "", -1)} -> 192.168.30.0/24 | D18: 8000 | E18: TCP | F18: Vaultwarden | G18: caddy | H18: private | I18: priv.moyer.wtf | J18: =IF(A18 <> "", LEFT(A18, FIND(".", A18) - 1) & "." & I18, "") -> vaultwarden.priv.moyer.wtf | K18: 443 | L18: TRUE | N18: TRUE | O18: TRUE | P18: fa-solid fa-lock
A19: homarr.homelab.moyer.wtf | B19: {=XLOOKUP(A19, NodeHostnames, NodeIPs, "")} -> 192.168.30.7 | C19: {=XLOOKUP(B19, Zones!$A$2:$A$9, Zones!$A$2:$A$9, "", -1)} -> 192.168.30.0/24 | D19: 7575 | E19: TCP | F19: Homarr | G19: caddy | H19: private | I19: priv.moyer.wtf | J19: =IF(A19 <> "", LEFT(A19, FIND(".", A19) - 1) & "." & I19, "") -> homarr.priv.moyer.wtf | K19: 443 | L19: FALSE | N19: TRUE | O19: TRUE | P19: fa-solid fa-house
A20: pbs.mgmt.moyer.wtf | B20: {=XLOOKUP(A20, NodeHostnames, NodeIPs, "")} -> 192.168.10.11 | C20: {=XLOOKUP(B20, Zones!$A$2:$A$9, Zones!$A$2:$A$9, "", -1)} -> 192.168.10.0/24 | D20: 8007 | E20: TCP | F20: Proxmox Backup Server | G20: caddy | H20: private | I20: priv.moyer.wtf | J20: =IF(A20 <> "", LEFT(A20, FIND(".", A20) - 1) & "." & I20, "") -> pbs.priv.moyer.wtf | K20: 443 | L20: TRUE | N20: TRUE | O20: TRUE | P20: fa-solid fa-database
A21: jellyfin.homelab.moyer.wtf | B21: {=XLOOKUP(A21, NodeHostnames, NodeIPs, "")} -> 192.168.30.9 | C21: {=XLOOKUP(B21, Zones!$A$2:$A$9, Zones!$A$2:$A$9, "", -1)} -> 192.168.30.0/24 | D21: 8096 | E21: TCP | F21: Jellyfin | G21: caddy | H21: public | I21: moyer.wtf | J21: =IF(A21 <> "", LEFT(A21, FIND(".", A21) - 1) & "." & I21, "") -> jellyfin.moyer.wtf | K21: 443 | L21: FALSE | N21: TRUE | O21: TRUE | P21: fa-solid fa-film
A22: openwebui.homelab.moyer.wtf | B22: {=XLOOKUP(A22, NodeHostnames, NodeIPs, "")} -> 192.168.30.10 | C22: {=XLOOKUP(B22, Zones!$A$2:$A$9, Zones!$A$2:$A$9, "", -1)} -> 192.168.30.0/24 | D22: 8080 | E22: TCP | F22: OpenwebUI | G22: caddy | H22: public | I22: moyer.wtf | J22: =IF(A22 <> "", LEFT(A22, FIND(".", A22) - 1) & "." & I22, "") -> openwebui.moyer.wtf | K22: 443 | L22: FALSE | N22: TRUE | O22: TRUE | P22: fa-solid fa-robot
A23: ollama.homelab.moyer.wtf | B23: {=XLOOKUP(A23, NodeHostnames, NodeIPs, "")} -> 192.168.30.11 | C23: {=XLOOKUP(B23, Zones!$A$2:$A$9, Zones!$A$2:$A$9, "", -1)} -> 192.168.30.0/24 | D23: 11434 | E23: TCP | F23: Ollama | G23: direct | H23: local | I23: moyer.wtf | J23: =IF(A23 <> "", LEFT(A23, FIND(".", A23) - 1) & "." & I23, "") -> ollama.moyer.wtf | N23: TRUE | O23: FALSE
A24: services.homelab.moyer.wtf | B24: {=XLOOKUP(A24, NodeHostnames, NodeIPs, "")} -> 192.168.30.5 | C24: {=XLOOKUP(B24, Zones!$A$2:$A$9, Zones!$A$2:$A$9, "", -1)} -> 192.168.30.0/24 | D24: 8000 | E24: TCP | F24: Service Directory | G24: caddy | H24: private | I24: priv.moyer.wtf | J24: =IF(A24 <> "", LEFT(A24, FIND(".", A24) - 1) & "." & I24, "") -> services.priv.moyer.wtf | K24: 443 | L24: FALSE | N24: TRUE | O24: FALSE
A25: freshrss.homelab.moyer.wtf | B25: {=XLOOKUP(A25, NodeHostnames, NodeIPs, "")} -> 192.168.30.16 | C25: {=XLOOKUP(B25, Zones!$A$2:$A$9, Zones!$A$2:$A$9, "", -1)} -> 192.168.30.0/24 | D25: 80 | E25: TCP | F25: FreshRSS | G25: caddy | H25: private | I25: priv.moyer.wtf | J25: =IF(A25 <> "", LEFT(A25, FIND(".", A25) - 1) & "." & I25, "") -> freshrss.priv.moyer.wtf | K25: 443 | L25: FALSE | N25: TRUE | O25: TRUE | P25: fa-solid fa-newspaper
A26: firefly-iii.homelab.moyer.wtf | B26: {=XLOOKUP(A26, NodeHostnames, NodeIPs, "")} -> 192.168.30.15 | C26: {=XLOOKUP(B26, Zones!$A$2:$A$9, Zones!$A$2:$A$9, "", -1)} -> 192.168.30.0/24 | D26: 80 | E26: TCP | F26: Firefly III | G26: caddy | H26: public | I26: moyer.wtf | J26: =IF(A26 <> "", LEFT(A26, FIND(".", A26) - 1) & "." & I26, "") -> firefly-iii.moyer.wtf | K26: 443 | L26: FALSE | N26: TRUE | O26: TRUE | P26: fa-solid fa-money-bill-1-wave
A27: gitea.homelab.moyer.wtf | B27: {=XLOOKUP(A27, NodeHostnames, NodeIPs, "")} -> 192.168.30.12 | C27: {=XLOOKUP(B27, Zones!$A$2:$A$9, Zones!$A$2:$A$9, "", -1)} -> 192.168.30.0/24 | D27: 3000 | E27: TCP | F27: Gitea | G27: caddy | H27: private | I27: priv.moyer.wtf | J27: =IF(A27 <> "", LEFT(A27, FIND(".", A27) - 1) & "." & I27, "") -> gitea.priv.moyer.wtf | K27: 443 | L27: FALSE | N27: TRUE | O27: TRUE | P27: fa-brands fa-square-git
A28: gitea-runner.homelab.moyer.wtf | B28: {=XLOOKUP(A28, NodeHostnames, NodeIPs, "")} -> 192.168.30.13 | C28: {=XLOOKUP(B28, Zones!$A$2:$A$9, Zones!$A$2:$A$9, "", -1)} -> 192.168.30.0/24 | E28: TCP | F28: Gitea Runner | G28: direct | H28: local | I28: moyer.wtf | J28: =IF(A28 <> "", LEFT(A28, FIND(".", A28) - 1) & "." & I28, "") -> gitea-runner.moyer.wtf | N28: TRUE | O28: FALSE
A29: uptime-kuma.mgmt.moyer.wtf | B29: {=XLOOKUP(A29, NodeHostnames, NodeIPs, "")} -> 192.168.10.16 | C29: {=XLOOKUP(B29, Zones!$A$2:$A$9, Zones!$A$2:$A$9, "", -1)} -> 192.168.10.0/24 | D29: 3001 | E29: TCP | F29: Uptime Kuma | G29: caddy | H29: private | I29: priv.moyer.wtf | J29: =IF(A29 <> "", LEFT(A29, FIND(".", A29) - 1) & "." & I29, "") -> uptime-kuma.priv.moyer.wtf | K29: 443 | L29: FALSE | N29: TRUE | O29: TRUE | P29: fa-solid fa-heart-pulse
A30: gitea.homelab.moyer.wtf | B30: {=XLOOKUP(A30, NodeHostnames, NodeIPs, "")} -> 192.168.30.12 | C30: {=XLOOKUP(B30, Zones!$A$2:$A$9, Zones!$A$2:$A$9, "", -1)} -> 192.168.30.0/24 | D30: 22 | E30: TCP | F30: Gitea SSH | G30: direct | H30: private | I30: priv.moyer.wtf | J30: =IF(A30 <> "", LEFT(A30, FIND(".", A30) - 1) & "." & I30, "") -> gitea.priv.moyer.wtf | M30: gitea-ssh.priv.moyer.wtf | N30: FALSE | O30: FALSE
A31: guac.homelab.moyer.wtf | B31: {=XLOOKUP(A31, NodeHostnames, NodeIPs, "")} -> 192.168.30.17 | C31: {=XLOOKUP(B31, Zones!$A$2:$A$9, Zones!$A$2:$A$9, "", -1)} -> 192.168.30.0/24 | D31: 8080 | E31: TCP | F31: Guacamole | G31: caddy | H31: public | I31: moyer.wtf | J31: =IF(A31 <> "", LEFT(A31, FIND(".", A31) - 1) & "." & I31, "") -> guac.moyer.wtf | K31: 443 | L31: FALSE | N31: TRUE | O31: TRUE | P31: fa-solid fa-desktop
A32: paperclip.homelab.moyer.wtf | B32: {=XLOOKUP(A32, NodeHostnames, NodeIPs, "")} -> 192.168.30.18 | C32: {=XLOOKUP(B32, Zones!$A$2:$A$9, Zones!$A$2:$A$9, "", -1)} -> 192.168.30.0/24 | D32: 3389 | E32: TCP | F32: RDP | G32: direct | H32: local | I32: priv.moyer.wtf | J32: =IF(A32 <> "", LEFT(A32, FIND(".", A32) - 1) & "." & I32, "") -> paperclip.priv.moyer.wtf | K32: 443 | L32: FALSE | N32: TRUE | O32: FALSE
A33: oxidized.homelab.moyer.wtf | B33: {=XLOOKUP(A33, NodeHostnames, NodeIPs, "")} -> 192.168.30.19 | C33: {=XLOOKUP(B33, Zones!$A$2:$A$9, Zones!$A$2:$A$9, "", -1)} -> 192.168.30.0/24 | D33: 8888 | E33: TCP | F33: Oxidized | G33: caddy | H33: private | I33: priv.moyer.wtf | J33: =IF(A33 <> "", LEFT(A33, FIND(".", A33) - 1) & "." & I33, "") -> oxidized.priv.moyer.wtf | K33: 443 | L33: FALSE | N33: TRUE | O33: FALSE
A34: www.homelab.moyer.wtf | B34: {=XLOOKUP(A34, NodeHostnames, NodeIPs, "")} -> 192.168.30.14 | C34: {=XLOOKUP(B34, Zones!$A$2:$A$9, Zones!$A$2:$A$9, "", -1)} -> 192.168.30.0/24 | D34: 8080 | E34: TCP | F34: WWW | G34: caddy | H34: public | I34: thomasmoyer.org | J34: =IF(A34 <> "", LEFT(A34, FIND(".", A34) - 1) & "." & I34, "") -> www.thomasmoyer.org | K34: 443 | L34: FALSE | M34: thomasmoyer.org | N34: TRUE | O34: TRUE | P34: fa-solid fa-house
A35: prometheus.mgmt.moyer.wtf | B35: {=XLOOKUP(A35, NodeHostnames, NodeIPs, "")} -> 192.168.10.5 | C35: {=XLOOKUP(B35, Zones!$A$2:$A$9, Zones!$A$2:$A$9, "", -1)} -> 192.168.10.0/24 | D35: 9090 | E35: TCP | F35: Prometheus | G35: caddy | H35: private | I35: priv.moyer.wtf | J35: =IF(A35 <> "", LEFT(A35, FIND(".", A35) - 1) & "." & I35, "") -> prometheus.priv.moyer.wtf | K35: 443 | L35: FALSE | N35: TRUE | O35: FALSE
A36: grafana.mgmt.moyer.wtf | B36: {=XLOOKUP(A36, NodeHostnames, NodeIPs, "")} -> 192.168.10.13 | C36: {=XLOOKUP(B36, Zones!$A$2:$A$9, Zones!$A$2:$A$9, "", -1)} -> 192.168.10.0/24 | D36: 3000 | E36: TCP | F36: Grafana | G36: caddy | H36: private | I36: priv.moyer.wtf | J36: =IF(A36 <> "", LEFT(A36, FIND(".", A36) - 1) & "." & I36, "") -> grafana.priv.moyer.wtf | K36: 443 | L36: FALSE | N36: TRUE | O36: TRUE | P36: fa-solid fa-chart-line
A37: tandoor.homelab.moyer.wtf | B37: {=XLOOKUP(A37, NodeHostnames, NodeIPs, "")} -> 192.168.30.4 | C37: {=XLOOKUP(B37, Zones!$A$2:$A$9, Zones!$A$2:$A$9, "", -1)} -> 192.168.30.0/24 | D37: 8002 | E37: TCP | F37: Tandoor | G37: caddy | H37: public | I37: moyer.wtf | J37: =IF(A37 <> "", LEFT(A37, FIND(".", A37) - 1) & "." & I37, "") -> tandoor.moyer.wtf | K37: 443 | L37: FALSE | N37: TRUE | O37: TRUE | P37: fa-solid fa-utensils
A38: apt-cache.homelab.moyer.wtf | B38: {=XLOOKUP(A38, NodeHostnames, NodeIPs, "")} -> 192.168.30.22 | C38: {=XLOOKUP(B38, Zones!$A$2:$A$9, Zones!$A$2:$A$9, "", -1)} -> 192.168.30.0/24 | D38: 3142 | E38: TCP | F38: APT-Cacher-NG | G38: direct | H38: private | I38: moyer.wtf | J38: =IF(A38 <> "", LEFT(A38, FIND(".", A38) - 1) & "." & I38, "") -> apt-cache.moyer.wtf | K38: 3142 | L38: FALSE | N38: TRUE | O38: FALSE

Sheet Helpers
A1: Protocols | B1: Proxmox Nodes
A2: tcp | B2: desktop-0
A3: udp | B3: meer5-0
A4: ucmp | B4: meer8-0
A5: gre | B5: meer8-1
B6: meer8-2

Sheet Static Address Lists
A1: List | B1: Address
A2: admin-laptop-ips | B2: 192.168.100.53
A3: admin-laptop-ips | B3: 192.168.100.54
A4: admin-laptop-ips | B4: 192.168.100.55
A5: admin-laptop-ips | B5: 192.168.100.56
A6: hlb-kuma-hosts | B6: 192.168.10.16
A7: hlb-prometheus-hosts | B7: 192.168.10.5

Sheet Firewall Rules
A1: Chain | B1: Order | C1: Kind | D1: Action | E1: In Interface List | F1: Out Interface List | G1: Src Address List | H1: Dst Address List | I1: Protocol | J1: Dst Port | K1: Connection State | L1: Connection NAT State | M1: Enabled | N1: Comment | O1: Managed By | P1: Type
A2: input | B2: 10 | C2: rule | D2: accept | E2: LAN | I2: icmp | K2: established | L2: related | M2: TRUE | N2: input established/related | P2: manual
A3: input | B3: 20 | C3: rule | D3: drop | L3: invalid | M3: TRUE | N3: drop invalid input | P3: manual
A4: input | B4: 30 | C4: rule | D4: drop | E4: WAN | M4: TRUE | N4: Block WAN mgmt | P4: manual
A5: input | B5: 40 | C5: rule | D5: accept | E5: LAN | I5: icmp | M5: TRUE | N5: allow ping to router (LAN) | P5: manual
A6: input | B6: 50 | C6: rule | D6: accept | E6: LAN | I6: udp | J6: 67,68 | M6: TRUE | N6: allow DHCP to router | P6: manual
A7: input | B7: 60 | C7: rule | D7: accept | E7: LAN | I7: udp | J7: 53 | M7: FALSE | N7: allow LAN DNS UDP to router | P7: manual
A8: input | B8: 70 | C8: rule | D8: accept | E8: LAN | I8: tcp | J8: 53 | M8: FALSE | N8: allow LAN DNS TCP to router | P8: manual
A9: input | B9: 80 | C9: rule | D9: accept | G9: admin-laptop-ips | M9: TRUE | N9: Allow Admin Laptop to Router Input | P9: manual
A10: input | B10: 90 | C10: anchor | M10: TRUE | N10: INPUT_DYNAMIC_RULES | P10: generator
A11: input | B11: 100 | C11: rule | D11: drop | M11: TRUE | N11: drop all other input | P11: manual
A12: forward | B12: 10 | C12: rule | D12: fasttrack-connection | K12: established | L12: related | M12: TRUE | N12: FastTrack | P12: manual
A13: forward | B13: 20 | C13: rule | D13: accept | K13: established | L13: related | M13: TRUE | N13: forward established/related | P13: manual
A14: forward | B14: 30 | C14: rule | D14: drop | K14: invalid | M14: TRUE | N14: drop invalid forward | P14: manual
A15: forward | B15: 40 | C15: rule | D15: accept | G15: admin-laptop-ips | H15: vlan-mgmt | M15: TRUE | N15: admin laptop -> mgmt | P15: manual
A16: forward | B16: 50 | C16: rule | D16: accept | E16: LAN | F16: WAN | M16: TRUE | N16: LAN -> WAN | P16: manual
A17: forward | B17: 60 | C17: rule | D17: accept | E17: LAN | H17: hlb-caddy-hosts | I17: tcp | J17: 80443 | M17: TRUE | N17: homelab -> caddy | P17: manual
A18: forward | B18: 61 | C18: rule | D18: accept | G18: hlb-kuma-hosts | M18: TRUE | N18: kuma access | P18: manual
A19: forward | B19: 62 | C19: rule | D19: accept | G19: hlb-prometheus-hosts | M19: TRUE | N19: prometheus access | P19: manual
A20: forward | B20: 63 | C20: rule | D20: accept | E20: LAN | H20: hlb-backend-tcp-3142 | I20: tcp | J20: 3142 | M20: TRUE | N20: apt-cacher-ng access | P20: manual
A21: forward | B21: 70 | C21: anchor | M21: TRUE | N21: FORWARD_DYNAMIC_RULES | P21: generator
A22: forward | B22: 900 | C22: rule | D22: drop | E22: LAN | F22: LAN | M22: TRUE | N22: block inter-VLAN (default deny) | P22: manual
A23: forward | B23: 1000 | C23: rule | D23: drop | M23: TRUE | N23: drop all other forward | P23: manual

Sheet NAT Rules
A1: Chain | B1: Order | C1: Kind | D1: Action | E1: In Interface List | F1: Out Interface List | G1: Src Address List | H1: Protocol | I1: Dst Port | J1: Enabled | K1: Comment | L1: Type
A2: srcnat | B2: 10 | C2: rule | D2: masquerade | F2: WAN | J2: TRUE | L2: manual
A3: dstnat | B3: 20 | C3: anchor | J3: TRUE | K3: NAT_DYNAMIC_RULES | L3: generator
